Workbook

Sheet READ ME
A1: Tennessee Elite Summer Basketball League — Budget Model
A4: What this file is | B4: A working budget model for a 16-team (8 boys / 8 girls) elite HS 5v5 summer league at Belmont University, first season Summer 2027. Two tiers: a Year 1 launch budget and a Full Vision (Year 3) budget.
A6: How to use it | B6: Every number in BLUE on the Assumptions and Staffing Plan tabs is an editable input. Everything in black is a formula that recalculates. Yellow cells are the assumptions that most need real quotes (Belmont rental, sponsor commitments).
A8: Color legend | B8: BLUE = editable input · BLACK = formula · GREEN = pulls from another tab · YELLOW fill = key assumption, verify with a real quote
A10: Tabs | B10: Assumptions → all levers. Year 1 Budget → launch season. Full Vision Budget → the ESPN-scale version. Revenue Scenarios → conservative / base / stretch. Sponsor Menu → sellable assets with price points. Staffing Plan → the team that runs it, with comp.
A12: Key sources | B12: Cost benchmarks: ZebraWeb officials pay survey; ArenaMediaCloud production calculator; Prep Athletic Director sponsorship pricing method; NCAA ECAG fee schedule; TSSAA 2024-25 Handbook & basketball calendar; Unrivaled/OTE reporting (ESPN, SportsPro, Front Office Sports). Venue costs are ESTIMATES — Belmont does not publish rates (contact osves@belmont.edu).
A14: Important caveat | B14: This model is planning-grade, not accounting-grade. Every venue, production, and sponsorship figure should be replaced with signed quotes as they arrive.

Sheet Assumptions
A1: Assumptions — every blue cell is editable
A3: LEAGUE STRUCTURE
A4: Teams per gender | B4: 8
A5: Genders (boys + girls) | B5: 2
A6: Total teams | B6: =B4*B5
A7: Roster size per team | B7: 10
A8: Total players | B8: =B6*B7
A9: Sessions per summer | B9: 2 | D9: Two 5-week sessions scheduled around the TSSAA dead period (~Jun 21 - Jul 4, 2027)
A10: Regular-season games per team per session | B10: 8 | D10: 2 games/week x 4 weeks; week 5 = playoffs
A11: Playoff games per gender per session | B11: 7 | D11: 8-team single-elim + 3rd place + final
A12: Games per session (both genders) | B12: =(B4*B10/2+B11)*B5
A13: Total league games per summer | B13: =B12*B9
A14: Nationals invitational games — Year 1 | B14: 0 | D14: Recommend launching Nationals in Year 2-3, not Year 1
A15: Nationals invitational games — Full Vision | B15: 24 | D15: 16 invited teams (8B/8G), ~10-day event aligned to NCAA July live periods
A16: Game/event days — Year 1 | B16: 44 | D16: ~20 game days/session + combine, draft, championship days
A17: Game/event days — Full Vision | B17: 64 | D17: Adds Nationals (~10 days) and more arena dates
A19: PLAYER FEES (your hybrid model)
A20: Tryout participants | B20: 600 | D20: Open tryouts across TN; fee credited toward season fee if drafted
A21: Tryout fee | B21: 50 | D21: Rolled into season fee for players who make it; combine fee waived for invitees
A22: Player season fee — Year 1 (net of tryout credit) | B22: 400 | D22: All-in for both sessions. vs $3,000-5,000+ typical AAU summer. Full Vision goal = $0 (fully sponsored)
A23: Player season fee — Full Vision | B23: 0 | D23: The anti-AAU endgame: sponsors fund everything
A25: COST RATES — shared drivers
A26: Officials — per official per game | B26: 150 | D26: UPGRADED: college-level officials (D2 crews) — the anti-AAU officiating standard. In-season college rates run $200-700/game; summer-league rate assumed $150
A27: Officials per game | B27: 3
A28: Certified athletic trainer — per event day | B28: 450 | D28: Per-diem ATs ~$40-75/hr; required by NCAA ECAG at every facility
A29: Game-day ops crew per day — Year 1 | B29: 800 | D29: Scorekeepers, clock, PA/DJ, gate, security
A30: Game-day ops crew per day — Full Vision | B30: 1400
A32: VENUE (estimates — get Belmont quote: osves@belmont.edu)
A33: Belmont practice facility court-hours — Year 1 | B33: 320 | D33: 2 courts, ~16 hrs/wk across 10 game weeks; 45,000 sq ft facility opened 2021, two full courts
A34: Practice facility rate per court-hour | B34: 90 | D34: Market: $50-150/hr for quality indoor courts; university premium assumed
A35: Curb Event Center days — Year 1 | B35: 6 | D35: Draft night + marquee weekends + championships. 5,085-seat arena
A36: Curb Event Center days — Full Vision | B36: 20 | D36: All game days in the arena, Unrivaled-style single-site look
A37: Curb Event Center per event day | B37: 7500 | D37: ESTIMATE. Comparable college arenas ~$2,500-10,000+/day plus staffing. Belmont does not publish rates
A38: Combine + draft venue & ops | B38: 30000 | D38: 2-day combine (testing, measurements, scrimmages) + televised-style draft night
A40: PRODUCTION & STREAMING
A41: Marquee broadcast games — Year 1 | B41: 16 | D41: 3-4 cameras, commentary, replay, graphics
A42: Marquee broadcast games — Full Vision | B42: 60
A43: Cost per marquee game — Year 1 | B43: 3500 | D43: Real broadcast cameras + crew (no PTZ): 3-4 manned broadcast cams, switcher, replay, graphics, 2 commentators — via Belmont media-college partnership / Nashville freelance broadcast market
A44: Cost per marquee game — Full Vision | B44: 6000 | D44: 8+ cam broadcast tier
A45: Cost per standard-stream game | B45: 400 | D45: Auto-cam (Pixellot/BallerTV-style) + student commentary; near-zero marginal cost after install
...

Sheet Staffing Plan
A1: Staffing Plan — the team that runs everything
A3: Role | B3: Type — Year 1 | C3: Year 1 Comp | D3: Type — Full Vision | E3: Full Vision Comp | F3: What they own
A4: FRONT OFFICE (league staff)
A5: Commissioner / League President (founder) | B5: Founder stipend | C5: 25000 | D5: Full-time | E5: 120000 | F5: Vision, sponsor relationships, media deals, public face of the league
A6: Director of Basketball Operations | B6: Seasonal contract | C6: 30000 | D6: Full-time | E6: 90000 | F6: Combine, draft, schedules, officials, rosters, competition rules
A7: Director of Partnerships & Revenue | B7: Seasonal + commission | C7: 25000 | D7: Full-time + commission | E7: 90000 | F7: Sponsor sales & activation, ticketing, renewals. Add 10% commission on new sponsor revenue
A8: Director of Media & Content | B8: Seasonal contract | C8: 30000 | D8: Full-time | E8: 85000 | F8: Streaming, social, brand, highlight engine — the Unrivaled-style growth lever
A9: Director of Events & Logistics | B9: Seasonal contract | C9: 25000 | D9: Full-time | E9: 75000 | F9: Venue, game-day ops, vendors, security, medical coverage
A10: Compliance & Player Welfare Coordinator | B10: Part-time | C10: 12000 | D10: Full-time | E10: 65000 | F10: TSSAA/NCAA ECAG compliance, eligibility, SafeSport, background checks, parent comms
A11: Finance & Admin | B11: Fractional bookkeeper | C11: 8000 | D11: Full-time ops manager | E11: 65000 | F11: Books, payroll, registrations, insurance
A12: Coordinators & interns (Belmont/Lipscomb/TSU sport mgmt) | B12: Stipends | C12: 6000 | D12: 4-6 paid coordinators | E12: 120000 | F12: Social clips, stats, team services, gameday support — recruit from local sport management programs
A14: TEAM STAFF (16 teams: 8 boys, 8 girls)
A15: Head Coaches x16 | B15: Season stipend $3,500 ea | C15: 56000 | D15: $8,000 ea | E15: 128000 | F15: Recruit college assistants, former pros, top trainers — NOT the players' own HS coaches (avoids TSSAA dead-period conflicts)
A16: Assistant Coaches x16 | B16: Season stipend $1,750 ea | C16: 28000 | D16: $4,000 ea | E16: 64000 | F16: One per team; development focus
A17: Interim/floater coach pool (4-6) | B17: Per-game stipends | C17: 6000 | D17: Per-game stipends | E17: 12000 | F17: League-wide substitutes covering absences — your 'interim coach' insurance policy
A19: GAME-DAY & PRODUCTION (variable — costed in the budget tabs, listed here for completeness)
A20: Officials (3-person certified crews) | F20: Costed per game in budget tabs
A21: Certified athletic trainers | F21: Required at every facility by NCAA ECAG; costed per event day
A22: Scorekeepers, clock, PA announcer, DJ, gate, security | F22: Costed per event day
A23: Producer, camera ops, commentators, highlight cutters, photographer | F23: Costed per game in production lines
A25: TOTAL — Front office | C25: =SUM(C5:C12) | E25: =SUM(E5:E12)
A26: TOTAL — Team staff (coaches) | C26: =SUM(C15:C17) | E26: =SUM(E15:E17)

Sheet Year 1 Budget
A1: Year 1 Budget: Year 1 (Summer 2027) — lean but legit
A3: EXPENSES
A4: Venue — practice facility court time | B4: =Assumptions!$B$33*Assumptions!$B$34 | D4: 2 courts at Belmont's 2021 practice facility
A5: Venue — Curb Event Center days | B5: =Assumptions!$B$35*Assumptions!$B$37 | D5: Draft night, marquee weekends, championships (5,085 seats)
A6: Combine + draft events | B6: =Assumptions!$B$38 | D6: 2-day combine with testing/measurements + a produced draft night
A7: Officials | B7: =(Assumptions!$B$13+Assumptions!$B$14)*Assumptions!$B$27*Assumptions!$B$26 | D7: 3-person certified crews, every game
A8: Athletic trainers / medical | B8: =Assumptions!$B$16*Assumptions!$B$28 | D8: Certified AT at every event day (NCAA ECAG requirement)
A9: Game-day operations | B9: =Assumptions!$B$16*Assumptions!$B$29 | D9: Scorekeepers, clock, PA/DJ, gate, security
A10: Front office | B10: ='Staffing Plan'!$C$25 | D10: See Staffing Plan tab
A11: Coaches (16 HC + 16 AC + interim pool) | B11: ='Staffing Plan'!$C$26 | D11: See Staffing Plan tab
A12: Uniforms & player gear | B12: =Assumptions!$B$8*Assumptions!$B$49 | D12: Premium sublimated home/away kits + bag
A13: Balls & equipment | B13: =Assumptions!$B$51 | D13: Wilson Evo NXT game balls + court equipment
A14: Production — marquee broadcast games | B14: =Assumptions!$B$41*Assumptions!$B$43 | D14: 3-4 cams, commentary, graphics, replay
A15: Production — standard streams (all other games) | B15: =((Assumptions!$B$13+Assumptions!$B$14)-Assumptions!$B$41)*Assumptions!$B$45 | D15: Auto-cam + student commentary; every game streamed
A16: Marketing & brand | B16: =Assumptions!$B$56 | D16: Brand system, content team, launch, paid social, PR
A17: Insurance | B17: =Assumptions!$B$58 | D17: CGL $1M/$2M + accident medical, NCAA additional insured
A18: Compliance (NCAA cert, USAB licenses, checks) | B18: =Assumptions!$B$60
A19: Tech & stats | B19: =Assumptions!$B$61
A20: Legal, entity & accounting | B20: =Assumptions!$B$63 | D20: 501(c)(3) formation + counsel
A21: Awards & trophies | B21: =Assumptions!$B$65
A22: Travel & hospitality | B22: =Assumptions!$B$67
A23: Subtotal | B23: =SUM(B4:B22)
A24: Contingency | B24: =B23*Assumptions!$B$70
A25: TOTAL EXPENSES | B25: =B23+B24
A27: REVENUE (base case — see Revenue Scenarios tab)
A28: Tryout fees | B28: =Assumptions!$B$20*Assumptions!$B$21 | D28: Credited toward season fee for drafted players — netted in the player-fee line note
A29: Player season fees | B29: =Assumptions!$B$8*Assumptions!$B$22 | D29: Net of tryout credit; ~10x cheaper than an AAU summer
A30: Title sponsor | B30: =Assumptions!$B$73
A31: Presenting sponsors | B31: =Assumptions!$B$74*Assumptions!$B$75
A32: Official category partners | B32: =Assumptions!$B$76*Assumptions!$B$77
A33: Team jersey partners | B33: =Assumptions!$B$78*Assumptions!$B$79
A34: Gate / tickets | B34: =Assumptions!$B$80
A35: Streaming rev share / league pass | B35: =Assumptions!$B$81
A36: Merchandise (net) | B36: =Assumptions!$B$82
A37: Donations & grants (501c3) | B37: =Assumptions!$B$83
A38: TOTAL REVENUE | B38: =SUM(B28:B37)
A40: NET SURPLUS / (FUNDING GAP) | B40: =B38-B25 | D40: A gap here = the founding-capital raise you need (investors, founding partners, grants)

Sheet Full Vision Budget
A1: Full Vision Budget: Full Vision (Year 3+) — the Unrivaled-scale version
A3: EXPENSES
A4: Venue — practice facility court time | B4: =Assumptions!$B$33*Assumptions!$B$34
A5: Venue — Curb Event Center days | B5: =Assumptions!$B$36*Assumptions!$B$37 | D5: Every game day in the arena — single-site, Unrivaled-style
A6: Combine + draft events | B6: =Assumptions!$B$38*2.5 | D6: Bigger produced combine + televised-style draft
A7: Officials | B7: =(Assumptions!$B$13+Assumptions!$B$15)*Assumptions!$B$27*(Assumptions!$B$26+15) | D7: Rate premium for top crews
A8: Athletic trainers / medical | B8: =Assumptions!$B$17*(Assumptions!$B$28+50)
A9: Game-day operations | B9: =Assumptions!$B$17*Assumptions!$B$30
A10: Front office (full-time) | B10: ='Staffing Plan'!$E$25 | D10: See Staffing Plan tab
A11: Coaches | B11: ='Staffing Plan'!$E$26 | D11: See Staffing Plan tab
A12: Uniforms & player gear | B12: =Assumptions!$B$8*Assumptions!$B$50 | D12: True team-catalog tier
A13: Balls & equipment | B13: =Assumptions!$B$51*1.5
A14: Production — marquee broadcast games | B14: =Assumptions!$B$42*Assumptions!$B$44 | D14: Broadcast-quality tier — the reel that gets you to ESPN conversations
A15: Production — standard streams | B15: =((Assumptions!$B$13+Assumptions!$B$15)-Assumptions!$B$42)*Assumptions!$B$46
A16: Player meals & transport | B16: =Assumptions!$B$52
A17: Sponsor-funded player NIL/appearance pool | B17: =Assumptions!$B$53 | D17: Legal under TSSAA NIL policy — no school marks, no coach facilitation
A18: Nationals — travel subsidies for invited teams | B18: =Assumptions!$B$68
A19: Nationals — event operations | B19: =Assumptions!$B$69
A20: Marketing & brand | B20: =Assumptions!$B$57
A21: Insurance | B21: =Assumptions!$B$59
A22: Compliance | B22: =Assumptions!$B$60*1.5
A23: Tech & stats | B23: =Assumptions!$B$62
A24: Legal & accounting | B24: =Assumptions!$B$64
A25: Awards & trophies | B25: =Assumptions!$B$66
A26: Subtotal | B26: =SUM(B4:B25)
A27: Contingency | B27: =B26*Assumptions!$B$70
A28: TOTAL EXPENSES | B28: =B26+B27
A30: REVENUE (base case — see Revenue Scenarios tab)
A31: Player fees | B31: =Assumptions!$B$8*Assumptions!$B$23 | D31: $0 — fully sponsored is the endgame
A32: Title sponsor | B32: =Assumptions!$B$86
A33: All other sponsorship | B33: =Assumptions!$B$87 | D33: See Sponsor Menu tab
A34: Gate / tickets | B34: =Assumptions!$B$88
A35: Media / streaming | B35: =Assumptions!$B$89
A36: Merchandise (net) | B36: =Assumptions!$B$90
A37: Nationals entry fees | B37: =Assumptions!$B$91
A38: Donations & grants | B38: =Assumptions!$B$92
A39: TOTAL REVENUE | B39: =SUM(B31:B38)
A41: NET SURPLUS / (FUNDING GAP) | B41: =B39-B28 | D41: A gap here = the founding-capital raise you need (investors, founding partners, grants)

Sheet Revenue Scenarios
A1: Year 1 Revenue Scenarios
A3: Scenario multipliers (editable)
A4: Conservative multiplier | B4: 0.6
A5: Base multiplier | B5: 1
A6: Stretch multiplier | B6: 1.4
E7: Multipliers apply to sponsorship, gate, streaming, merch & grants. Player/tryout fees held flat.
A9: Line | B9: Conservative | C9: Base | D9: Stretch | E9: Notes
A10: ='Year 1 Budget'!$A$28 | B10: ='Year 1 Budget'!$B$28 | C10: ='Year 1 Budget'!$B$28 | D10: ='Year 1 Budget'!$B$28
A11: ='Year 1 Budget'!$A$29 | B11: ='Year 1 Budget'!$B$29 | C11: ='Year 1 Budget'!$B$29 | D11: ='Year 1 Budget'!$B$29
A12: ='Year 1 Budget'!$A$30 | B12: ='Year 1 Budget'!$B$30*$B$4 | C12: ='Year 1 Budget'!$B$30*$B$5 | D12: ='Year 1 Budget'!$B$30*$B$6
A13: ='Year 1 Budget'!$A$31 | B13: ='Year 1 Budget'!$B$31*$B$4 | C13: ='Year 1 Budget'!$B$31*$B$5 | D13: ='Year 1 Budget'!$B$31*$B$6
A14: ='Year 1 Budget'!$A$32 | B14: ='Year 1 Budget'!$B$32*$B$4 | C14: ='Year 1 Budget'!$B$32*$B$5 | D14: ='Year 1 Budget'!$B$32*$B$6
A15: ='Year 1 Budget'!$A$33 | B15: ='Year 1 Budget'!$B$33*$B$4 | C15: ='Year 1 Budget'!$B$33*$B$5 | D15: ='Year 1 Budget'!$B$33*$B$6
A16: ='Year 1 Budget'!$A$34 | B16: ='Year 1 Budget'!$B$34*$B$4 | C16: ='Year 1 Budget'!$B$34*$B$5 | D16: ='Year 1 Budget'!$B$34*$B$6
A17: ='Year 1 Budget'!$A$35 | B17: ='Year 1 Budget'!$B$35*$B$4 | C17: ='Year 1 Budget'!$B$35*$B$5 | D17: ='Year 1 Budget'!$B$35*$B$6
A18: ='Year 1 Budget'!$A$36 | B18: ='Year 1 Budget'!$B$36*$B$4 | C18: ='Year 1 Budget'!$B$36*$B$5 | D18: ='Year 1 Budget'!$B$36*$B$6
A19: ='Year 1 Budget'!$A$37 | B19: ='Year 1 Budget'!$B$37*$B$4 | C19: ='Year 1 Budget'!$B$37*$B$5 | D19: ='Year 1 Budget'!$B$37*$B$6
A20: TOTAL REVENUE | B20: =SUM(B10:B19) | C20: =SUM(C10:C19) | D20: =SUM(D10:D19)
A21: Total expenses (Year 1) | B21: ='Year 1 Budget'!$B$25 | C21: ='Year 1 Budget'!$B$25 | D21: ='Year 1 Budget'!$B$25
A22: NET SURPLUS / (FUNDING GAP) | B22: =B20-B21 | C22: =C20-C21 | D22: =D20-D21

Sheet Sponsor Menu
A1: Sponsor Menu — sellable assets & Year 1 price points
A3: Asset | B3: # Avail | C3: Price low | D3: Price high | E3: Potential (mid) | F3: What the sponsor gets
A4: Title / naming rights ('The ___ League') | B4: 1 | C4: 50000 | D4: 75000 | E4: =B4*(C4+D4)/2 | F4: Name in league name, center court, all broadcasts, jerseys, every social post
A5: Presenting partner ('presented by') | B5: 2 | C5: 20000 | D5: 30000 | E5: =B5*(C5+D5)/2 | F5: Logo lockup on all media, in-arena signage, PA reads, category exclusivity
A6: Official ball / apparel / footwear partner | B6: 3 | C6: 10000 | D6: 20000 | E6: =B6*(C6+D6)/2 | F6: Product on court every game + retail activation rights
A7: Official category partner (bank, auto, health, QSR, drink) | B7: 5 | C7: 7500 | D7: 15000 | E7: =B7*(C7+D7)/2 | F7: Category exclusivity, court decal, stream ad slots, booth
A8: Team jersey front partner (per team) | B8: 16 | C8: 4000 | D8: 6000 | E8: =B8*(C8+D8)/2 | F8: Front-of-jersey patch on one team, in every game + highlight clip
A9: Court logo decal | B9: 4 | C9: 5000 | D9: 7500 | E9: =B9*(C9+D9)/2 | F9: On-court logo visible in every stream frame
A10: Combine title sponsor | B10: 1 | C10: 10000 | D10: 15000 | E10: =B10*(C10+D10)/2 | F10: Naming of the combine weekend, testing-station branding, content series
A11: Draft night title sponsor | B11: 1 | C11: 10000 | D11: 15000 | E11: =B11*(C11+D11)/2 | F11: Naming of draft night, stage branding, draft-cap co-brand
A12: Nationals invitational title (when launched) | B12: 1 | C12: 25000 | D12: 50000 | E12: =B12*(C12+D12)/2 | F12: Naming of the national event
A13: Halftime / in-game segment ('Play of the Night by ___') | B13: 6 | C13: 2000 | D13: 4000 | E13: =B13*(C13+D13)/2 | F13: Branded recurring content segment, Unrivaled 'Galaxy Game Winner' style
A14: Stream broadcast ad package (per session) | B14: 8 | C14: 2500 | D14: 5000 | E14: =B14*(C14+D14)/2 | F14: 30-sec spots + lower-thirds across all streamed games
A15: Awards & MVP sponsor | B15: 2 | C15: 4000 | D15: 6000 | E15: =B15*(C15+D15)/2 | F15: Naming on MVP, All-League team, trophy presentations
... A18: Digital / website / app partner | B18: 2 | C18: 3000 | D18: 6000 | E18: =B18*(C18+D18)/2 | F18: Logo on stats hub, schedules, recruiting profiles
A19: TOTAL MENU POTENTIAL (if fully sold, mid prices) | E19: =SUM(E4:E18)
A21: Pricing method: $0.10-$2.00 per audience member x visibility multiplier (jersey 2-4x, PA/banner 1.5x), category exclusivity 2-5x premium — Prep Athletic Director model. Streaming impressions are the upsell lever.
